2013-07-10 01:21:01,982 INFO: calzonee startup [in /home/pi/calzone/app/__init__.py:42]
2013-07-10 01:21:29,784 ERROR: Exception on /arm [GET] [in /home/pi/calzone/flask/local/lib/python2.7/site-packages/flask/app.py:1306]
Traceback (most recent call last):
  File "/home/pi/calzone/flask/local/lib/python2.7/site-packages/flask/app.py", line 1687, in wsgi_app
    response = self.full_dispatch_request()
  File "/home/pi/calzone/flask/local/lib/python2.7/site-packages/flask/app.py", line 1360, in full_dispatch_request
    rv = self.handle_user_exception(e)
  File "/home/pi/calzone/flask/local/lib/python2.7/site-packages/flask/app.py", line 1358, in full_dispatch_request
    rv = self.dispatch_request()
  File "/home/pi/calzone/flask/local/lib/python2.7/site-packages/flask/app.py", line 1344, in dispatch_request
    return self.view_functions[rule.endpoint](**req.view_args)
  File "/home/pi/calzone/flask/local/lib/python2.7/site-packages/flask_login.py", line 496, in decorated_view
    return fn(*args, **kwargs)
  File "/home/pi/calzone/app/views.py", line 119, in arm
    db.session.commit()  #write data
  File "/home/pi/calzone/flask/local/lib/python2.7/site-packages/sqlalchemy/orm/scoping.py", line 114, in do
    return getattr(self.registry(), name)(*args, **kwargs)
  File "/home/pi/calzone/flask/local/lib/python2.7/site-packages/sqlalchemy/orm/session.py", line 703, in commit
    self.transaction.commit()
  File "/home/pi/calzone/flask/local/lib/python2.7/site-packages/sqlalchemy/orm/session.py", line 361, in commit
    self._prepare_impl()
  File "/home/pi/calzone/flask/local/lib/python2.7/site-packages/sqlalchemy/orm/session.py", line 340, in _prepare_impl
    self.session.flush()
  File "/home/pi/calzone/flask/local/lib/python2.7/site-packages/sqlalchemy/orm/session.py", line 1718, in flush
    self._flush(objects)
  File "/home/pi/calzone/flask/local/lib/python2.7/site-packages/sqlalchemy/orm/session.py", line 1789, in _flush
    flush_context.execute()
  File "/home/pi/calzone/flask/local/lib/python2.7/site-packages/sqlalchemy/orm/unitofwork.py", line 331, in execute
    rec.execute(self)
  File "/home/pi/calzone/flask/local/lib/python2.7/site-packages/sqlalchemy/orm/unitofwork.py", line 475, in execute
    uow
  File "/home/pi/calzone/flask/local/lib/python2.7/site-packages/sqlalchemy/orm/persistence.py", line 64, in save_obj
    table, insert)
  File "/home/pi/calzone/flask/local/lib/python2.7/site-packages/sqlalchemy/orm/persistence.py", line 558, in _emit_insert_statements
    execute(statement, params)
  File "/home/pi/calzone/flask/local/lib/python2.7/site-packages/sqlalchemy/engine/base.py", line 1449, in execute
    params)
  File "/home/pi/calzone/flask/local/lib/python2.7/site-packages/sqlalchemy/engine/base.py", line 1584, in _execute_clauseelement
    compiled_sql, distilled_params
  File "/home/pi/calzone/flask/local/lib/python2.7/site-packages/sqlalchemy/engine/base.py", line 1698, in _execute_context
    context)
  File "/home/pi/calzone/flask/local/lib/python2.7/site-packages/sqlalchemy/engine/base.py", line 1691, in _execute_context
    context)
  File "/home/pi/calzone/flask/local/lib/python2.7/site-packages/sqlalchemy/engine/default.py", line 331, in do_execute
    cursor.execute(statement, parameters)
OperationalError: (OperationalError) attempt to write a readonly database u'INSERT INTO history (source, event, timestamp) VALUES (?, ?, ?)' (u'evanmj', 'Armed By User', '2013-07-10 01:21:29.754837')
